<?xml version="1.0" ?>
<!-- =================================================================================== -->
<!-- |    This document was autogenerated by xacro from /home/change/catkin_ws/src/mobot/urdf/mobot.urdf.xacro | -->
<!-- |    EDITING THIS FILE BY HAND IS NOT RECOMMENDED                                 | -->
<!-- =================================================================================== -->
<robot name="car_mbot">
  <!--skid_steer_drive_controller-->
  <gazebo>
    <plugin name="skid_steer_drive_controller" filename="libgazebo_ros_skid_steer_drive.so">
      <updateRate>100.0</updateRate>
      <robotNamespace>/mobot</robotNamespace>
      <odometryFrame>odom</odometryFrame>
      <leftFrontJoint>front_left_wheel_joint</leftFrontJoint>
      <rightFrontJoint>front_right_wheel_joint</rightFrontJoint>
      <leftRearJoint>back_left_wheel_joint</leftRearJoint>
      <rightRearJoint>back_right_wheel_joint</rightRearJoint>
      <wheelSeparation>0.4</wheelSeparation>
      <wheelDiameter>0.215</wheelDiameter>
      <robotBaseFrame>robot_footprint</robotBaseFrame>
      <torque>20</torque>
      <publishTf>true</publishTf>
      <publishOdom>true</publishOdom>
      <publishOdomTF>true</publishOdomTF>
      <publishWheelTF>true</publishWheelTF>
      <commandTopic>cmd_vel</commandTopic>
      <topicName>cmd_vel</topicName>
      <broadcastTF>true</broadcastTF>
    </plugin>
  </gazebo>
  <gazebo reference="camera">
    <sensor name="camera_sensor" type="camera">
      <update_rate>30.0</update_rate>
      <always_on>1</always_on>
      <camera name="camera">
        <horizontal_fov>1.3962634</horizontal_fov>
        <image>
          <width>800</width>
          <height>800</height>
          <format>R8G8B8</format>
        </image>
        <clip>
          <near>0.02</near>
          <far>300</far>
        </clip>
        <distortion>
          <k1>0.0</k1>
          <k2>0.0</k2>
          <k3>0.0</k3>
          <p1>0.0</p1>
          <p2>0.0</p2>
          <center>0.5 0.5</center>
        </distortion>
      </camera>
      <plugin filename="libgazebo_ros_camera.so" name="camera_controller">
        <ros>
          <namespace>/mobot</namespace>
          <argument>camera/image_raw:=/mobot/camera/image</argument>
          <argument>camera/camera_info:=/mobot/camera/image/camera_info</argument>
        </ros>
        <camera_name>camera</camera_name>
        <frame_name>camera</frame_name>
        <hack_baseline>0.07</hack_baseline>
      </plugin>
    </sensor>
  </gazebo>
  <gazebo reference="hokuyo">
    <sensor type="ray" name="head_hokuyo_sensor">
      <pose>0 0 0 0 0 0</pose>
      <visualize>false</visualize>
      <update_rate>30</update_rate>
      <ray>
        <scan>
          <horizontal>
            <samples>1800</samples>
            <resolution>1</resolution> 
            <min_angle>-1.5707963</min_angle>
            <max_angle>+1.5707963</max_angle>
          </horizontal>
        </scan>
        <range>
          <min>0.1</min>
          <max>30.0</max>
          <resolution>0.01</resolution>
        </range>
        <noise>
          <type>gaussian</type> 
          <mean>0.0</mean>
          <stddev>0.01</stddev>
        </noise>
      </ray>
      <plugin name="gazebo_ros_head_hokuyo_controller" filename="libgazebo_ros_laser.so">
        <topicName>scan</topicName>
        <frameName>robot_footprint</frameName>
      </plugin>
    </sensor>
  </gazebo>
  <link name="robot_footprint"/>
  <joint name="robot_footprint_joint" type="fixed">
    <origin rpy="0 0 0" xyz="0 0 0"/>
    <parent link="robot_footprint"/>
    <child link="chassis"/>
  </joint>
  <link name="chassis">
    <pose>0 0 0.1 0 0 0</pose>
    <inertial>
      <mass value="15.0"/>
      <origin rpy=" 0 0 0" xyz="0.0 0 0"/>
      <inertia ixx="0.1" ixy="0" ixz="0" iyy="0.1" iyz="0" izz="0.1"/>
    </inertial>
    <collision name="collision">
      <origin rpy=" 0 0 0" xyz="-0.144 -0.073 0"/>
      <geometry>
        <mesh filename="/home/change/catkin_ws/src/car_mbot/meshes/base_link.STL"/>
      </geometry>
    </collision>
    <visual name="chassis_visual">
      <origin rpy=" 0 0 0" xyz="-0.144 -0.073 0"/>
      <geometry>
        <mesh filename="/home/change/catkin_ws/src/car_mbot/meshes/base_link.STL"/>
      </geometry>
    </visual>
  </link>
  <link name="front_left_wheel">
    <inertial>
      <mass value="5.0"/>
      <origin rpy=" 0 0 0" xyz="0.0 0 0"/>
      <inertia ixx="0.1" ixy="0" ixz="0" iyy="0.1" iyz="0" izz="0.1"/>
    </inertial>
    <visual>
      <origin rpy=" 0 0 0" xyz="0.0 0 0"/>
      <geometry>
        <mesh filename="/home/change/catkin_ws/src/car_mbot/meshes/Wheel_FL.STL"/>
      </geometry>
    </visual>
    <collision>
      <origin rpy=" 0 0 0" xyz="0.0 0 0"/>
      <geometry>
        <mesh filename="/home/change/catkin_ws/src/car_mbot/meshes/Wheel_FL.STL"/>
      </geometry>
    </collision>
  </link>
  <link name="back_left_wheel">
    <inertial>
      <mass value="5.0"/>
      <origin rpy=" 0 0 0" xyz="0.0 0 0"/>
      <inertia ixx="0.1" ixy="0" ixz="0" iyy="0.1" iyz="0" izz="0.1"/>
    </inertial>
    <visual>
      <origin rpy=" 0 0 0" xyz="0.0 0 0"/>
      <geometry>
        <mesh filename="/home/change/catkin_ws/src/car_mbot/meshes/Wheel_RL.STL" />
      </geometry>
    </visual>
    <collision>
      <origin rpy=" 0 0 0" xyz="0.0 0 0"/>
      <geometry>
        <mesh filename="/home/change/catkin_ws/src/car_mbot/meshes/Wheel_RL.STL" />
      </geometry>
    </collision>
  </link>
  <link name="front_right_wheel">
    <inertial>
      <mass value="5.0"/>
      <origin rpy=" 0 0 0" xyz="0.0 0 0"/>
      <inertia ixx="0.1" ixy="0" ixz="0" iyy="0.1" iyz="0" izz="0.1"/>
    </inertial>
    <visual>
      <origin rpy=" 0 0 0" xyz="0.0 0 0"/>
      <geometry>
        <mesh filename="/home/change/catkin_ws/src/car_mbot/meshes/Wheel_FR.STL"/>
      </geometry>
    </visual>
    <collision>
      <origin rpy=" 0 0 0" xyz="0.0 0 0"/>
      <geometry>
        <mesh filename="/home/change/catkin_ws/src/car_mbot/meshes/Wheel_FR.STL"/>
      </geometry>
    </collision>
  </link>
  <link name="back_right_wheel">
    <inertial>
      <mass value="5.0"/>
      <origin rpy=" 0 0 0" xyz="0.0 0 0"/>
      <inertia ixx="0.1" ixy="0" ixz="0" iyy="0.1" iyz="0" izz="0.1"/>
    </inertial>
    <visual>
      <origin rpy=" 0 0 0" xyz="0.0 0 0"/>
      <geometry>
        <mesh filename="/home/change/catkin_ws/src/car_mbot/meshes/Wheel_RR.STL" />
      </geometry>
    </visual>
    <collision>
      <origin rpy=" 0 0 0" xyz="0.0 0 0"/>
      <geometry>
        <mesh filename="/home/change/catkin_ws/src/car_mbot/meshes/Wheel_RR.STL" />
      </geometry>
    </collision>
  </link>
  <link name="camera">
    <inertial>
      <mass value="0.1"/>
      <origin rpy=" 0 0 0" xyz="0.05 0.05 0.05"/>
      <inertia ixx="1e-6" ixy="0" ixz="0" iyy="1e-6" iyz="0" izz="1e-6"/>
    </inertial>
    <visual name="camera_visual">
      <origin rpy="0 0 0" xyz="0 0 0"/>
      <geometry>
        <box size="0.05 0.05 0.05"/>
      </geometry>
    </visual>
    <collision name="camera_colision">
      <origin rpy="0 0 0" xyz="0 0 0"/>
      <geometry>
        <box size="0.05 0.05 0.05"/>
      </geometry>
    </collision>
  </link>
  <link name="hokuyo">
    <inertial>
      <mass value="1e-5"/>
      <origin rpy=" 0 0 0" xyz="0 0 0"/>
      <inertia ixx="1e-6" ixy="0" ixz="0" iyy="1e-6" iyz="0" izz="1e-6"/>
    </inertial>
    <visual name="hokuyo_visual">
      <origin rpy="0 0 0" xyz="0 0 0"/>
      <geometry>
        <!-- <mesh filename="$(find mobot)/meshes/hokuyo.dae"/> -->
        <box size="0.05 0.05 0.05"/>
      </geometry>
    </visual>
    <collision name="hokuyo_colision">
      <origin rpy="0 0 0" xyz="0 0 0"/>
      <geometry>
        <box size="0.1 0.1 0.1"/>
      </geometry>
    </collision>
  </link>
  <joint name="front_left_wheel_joint" type="continuous">
    <origin rpy="0 0 0" xyz="0.14 0.07 0"/>
    <child link="front_left_wheel"/>
    <parent link="chassis"/>
    <axis rpy="0 0 0" xyz="0 1 0"/>
    <limit effort="10000" velocity="1000"/>
    <dynamics damping="1.0" friction="1.0"/>
  </joint>
  <joint name="front_right_wheel_joint" type="continuous">
    <origin rpy="0 0 0" xyz="0.14 -0.07 0"/>
    <child link="front_right_wheel"/>
    <parent link="chassis"/>
    <axis rpy="0 0 0" xyz="0 1 0"/>
    <limit effort="10000" velocity="1000"/>
    <dynamics damping="1.0" friction="1.0"/>
  </joint>
  <joint name="back_left_wheel_joint" type="continuous">
    <origin rpy="0 0 0" xyz="-0.14 0.07 0"/>
    <child link="back_left_wheel"/>
    <parent link="chassis"/>
    <axis rpy="0 0 0" xyz="0 1 0"/>
    <limit effort="10000" velocity="1000"/>
    <dynamics damping="1.0" friction="1.0"/>
  </joint>
  <joint name="back_right_wheel_joint" type="continuous">
    <origin rpy="0 0 0" xyz="-0.14 -0.07 0"/>
    <child link="back_right_wheel"/>
    <parent link="chassis"/>
    <axis rpy="0 0 0" xyz="0 1 0"/>
    <limit effort="10000" velocity="1000"/>
    <dynamics damping="1.0" friction="1.0"/>
  </joint>
  <joint name="camera_joint" type="fixed">
    <origin rpy="0 0 0" xyz="0.2 0 0"/>
    <child link="camera"/>
    <parent link="chassis"/>
    <axis rpy="0 0 0" xyz="0 1 0"/>
  </joint>
  <joint name="hokuyo_joint" type="fixed">
    <origin rpy="0 0 0" xyz="0.15 0 0.1"/>
    <child link="hokuyo"/>
    <parent link="chassis"/>
    <axis rpy="0 0 0" xyz="0 1 0"/>
  </joint>
  <gazebo reference="chassis">
    <material>Gazebo/Black</material>
  </gazebo>
  <gazebo reference="camera">
    <material>Gazebo/Red</material>
  </gazebo>
  <gazebo reference="hokuyo">
    <material>Gazebo/White</material>
  </gazebo>
  <gazebo reference="front_left_wheel">
    <material>Gazebo/Gray</material>
  </gazebo>
  <gazebo reference="back_left_wheel">
    <material>Gazebo/Gray</material>
  </gazebo>
  <gazebo reference="front_right_wheel">
    <material>Gazebo/Gray</material>
  </gazebo>
  <gazebo reference="back_right_wheel">
    <material>Gazebo/Gray</material>
  </gazebo>
</robot>
